2025-10-09 12:39:55,158 - DEBUG - Program başlatıldı

2025-10-09 12:39:59,582 - DEBUG - Bir dosya seçildi --> /Users/tuakpina/Projects/PythonProjects/PyQt6/CsvToSql/table.csv
2025-10-09 12:40:00,928 - DEBUG - Çalıştır butonuna basıldı
2025-10-09 12:40:02,429 - DEBUG - Programdan çıkış yapıldı

2025-10-09 12:40:06,889 - DEBUG - Program başlatıldı

2025-10-09 12:40:12,481 - DEBUG - Programdan çıkış yapıldı

2025-10-09 12:40:25,738 - DEBUG - Program başlatıldı
2025-10-09 12:40:29,654 - DEBUG - Bir dosya seçildi --> /Users/tuakpina/Projects/PythonProjects/PyQt6/CsvToSql/table.csv
2025-10-09 12:40:30,562 - DEBUG - Çalıştır butonuna basıldı
2025-10-09 12:40:31,930 - DEBUG - Programdan çıkış yapıldı

2025-10-09 12:40:35,359 - DEBUG - Program başlatıldı
2025-10-09 12:40:38,046 - DEBUG - Çalıştır butonuna basıldı
2025-10-09 12:40:38,047 - ERROR - run_buton: 'MainWindow' object has no attribute 'csv_path'
Traceback (most recent call last):
  File "/Users/tuakpina/Projects/PythonProjects/PyQt6/CsvToSql/main.py", line 56, in run_button
    self.result = convert(self.csv_path)
                          ^^^^^^^^^^^^^
AttributeError: 'MainWindow' object has no attribute 'csv_path'
2025-10-09 12:40:38,880 - DEBUG - Programdan çıkış yapıldı

2025-10-09 12:41:15,137 - DEBUG - Program başlatıldı
2025-10-09 12:41:16,379 - DEBUG - Çalıştır butonuna basıldı
2025-10-09 12:41:16,380 - ERROR - run_buton: 'MainWindow' object has no attribute 'csv_path'
Traceback (most recent call last):
  File "/Users/tuakpina/Projects/PythonProjects/PyQt6/CsvToSql/main.py", line 56, in run_button
    self.result = convert(self.csv_path)
                          ^^^^^^^^^^^^^
AttributeError: 'MainWindow' object has no attribute 'csv_path'
2025-10-09 12:41:19,214 - DEBUG - Programdan çıkış yapıldı

2025-10-09 12:41:46,828 - DEBUG - Program başlatıldı
2025-10-09 12:41:47,678 - DEBUG - Çalıştır butonuna basıldı
2025-10-09 12:41:47,678 - ERROR - run_buton: [Errno 2] No such file or directory: ''
Traceback (most recent call last):
  File "/Users/tuakpina/Projects/PythonProjects/PyQt6/CsvToSql/main.py", line 58, in run_button
    self.result.exec()
    ~~~~~~~~~~~~~~~~^^
  File "/Users/tuakpina/Projects/PythonProjects/PyQt6/CsvToSql/convert.py", line 9, in exec
    df = pd.read_csv(self.file_path, encoding="utf-8")
  File "/Library/Frameworks/Python.framework/Versions/3.13/lib/python3.13/site-packages/pandas/io/parsers/readers.py", line 1026, in read_csv
    return _read(filepath_or_buffer, kwds)
  File "/Library/Frameworks/Python.framework/Versions/3.13/lib/python3.13/site-packages/pandas/io/parsers/readers.py", line 620, in _read
    parser = TextFileReader(filepath_or_buffer, **kwds)
  File "/Library/Frameworks/Python.framework/Versions/3.13/lib/python3.13/site-packages/pandas/io/parsers/readers.py", line 1620, in __init__
    self._engine = self._make_engine(f, self.engine)
                   ~~~~~~~~~~~~~~~~~^^^^^^^^^^^^^^^^
  File "/Library/Frameworks/Python.framework/Versions/3.13/lib/python3.13/site-packages/pandas/io/parsers/readers.py", line 1880, in _make_engine
    self.handles = get_handle(
                   ~~~~~~~~~~^
        f,
        ^^
    ...<6 lines>...
        storage_options=self.options.get("storage_options", None),
        ^^^^^^^^^^^^^^^^^^^^^^^^^^^^^^^^^^^^^^^^^^^^^^^^^^^^^^^^^^
    )
    ^
  File "/Library/Frameworks/Python.framework/Versions/3.13/lib/python3.13/site-packages/pandas/io/common.py", line 882, in get_handle
    handle = open(handle, ioargs.mode)
FileNotFoundError: [Errno 2] No such file or directory: ''
2025-10-09 12:41:49,365 - DEBUG - Programdan çıkış yapıldı

2025-10-09 12:42:18,649 - DEBUG - Program başlatıldı
2025-10-09 12:42:21,432 - DEBUG - Programdan çıkış yapıldı

2025-10-09 12:51:52,830 - DEBUG - Program başlatıldı
2025-10-09 12:52:45,741 - DEBUG - Program başlatıldı
2025-10-09 12:52:52,258 - DEBUG - Program başlatıldı
2025-10-09 12:52:56,219 - DEBUG - Program başlatıldı
2025-10-09 12:53:03,684 - DEBUG - Program başlatıldı
2025-10-09 12:53:18,582 - DEBUG - Bir dosya seçildi --> 
2025-10-09 12:53:19,424 - DEBUG - Programdan çıkış yapıldı

2025-10-09 12:53:48,130 - DEBUG - Program başlatıldı
2025-10-09 12:54:06,324 - DEBUG - Program başlatıldı
2025-10-09 12:54:24,980 - DEBUG - Program başlatıldı
2025-10-09 12:54:40,986 - DEBUG - Program başlatıldı
2025-10-09 14:16:52,525 - DEBUG - Program başlatıldı
2025-10-09 14:16:54,092 - DEBUG - Program başlatıldı
2025-10-09 14:17:04,649 - DEBUG - Program başlatıldı
2025-10-09 14:17:37,080 - DEBUG - Program başlatıldı
2025-10-09 14:17:55,997 - DEBUG - Programdan çıkış yapıldı

2025-10-09 14:18:02,113 - DEBUG - Program başlatıldı
2025-10-09 14:18:05,544 - DEBUG - Bir dosya seçildi --> 
2025-10-09 14:18:16,544 - DEBUG - Programdan çıkış yapıldı

2025-10-09 15:01:01,214 - DEBUG - Program başlatıldı
2025-10-09 15:01:03,774 - DEBUG - Programdan çıkış yapıldı

2025-10-09 15:01:20,121 - DEBUG - Program başlatıldı
2025-10-09 15:02:15,157 - DEBUG - Program başlatıldı
2025-10-09 15:02:32,753 - DEBUG - Program başlatıldı
2025-10-09 15:02:38,575 - DEBUG - Programdan çıkış yapıldı

2025-10-09 15:02:43,285 - DEBUG - Program başlatıldı
2025-10-09 15:02:49,491 - DEBUG - Programdan çıkış yapıldı

2025-10-09 15:02:56,986 - DEBUG - Program başlatıldı
2025-10-09 15:03:06,874 - DEBUG - Programdan çıkış yapıldı

2025-10-09 15:03:25,696 - DEBUG - Program başlatıldı
2025-10-09 15:03:32,557 - DEBUG - Programdan çıkış yapıldı

2025-10-09 15:04:37,811 - DEBUG - Program başlatıldı
2025-10-09 15:04:40,955 - DEBUG - Programdan çıkış yapıldı

2025-10-09 15:05:40,854 - DEBUG - Program başlatıldı
2025-10-09 15:05:45,607 - DEBUG - Programdan çıkış yapıldı

2025-10-09 15:05:57,071 - DEBUG - Program başlatıldı
2025-10-09 15:06:05,839 - DEBUG - Programdan çıkış yapıldı

2025-10-09 15:06:11,941 - DEBUG - Program başlatıldı
2025-10-09 15:06:15,731 - DEBUG - Bir dosya seçildi --> 
2025-10-09 15:06:22,888 - DEBUG - Programdan çıkış yapıldı

2025-10-09 15:06:51,559 - DEBUG - Program başlatıldı
2025-10-09 15:06:59,922 - DEBUG - Programdan çıkış yapıldı

2025-10-09 15:20:30,428 - DEBUG - Program başlatıldı
2025-10-09 15:20:59,825 - DEBUG - Programdan çıkış yapıldı

2025-10-09 15:21:41,653 - DEBUG - Program başlatıldı
2025-10-09 15:21:46,356 - DEBUG - Programdan çıkış yapıldı

2025-10-09 15:22:18,002 - DEBUG - Program başlatıldı
2025-10-09 15:22:22,274 - DEBUG - Programdan çıkış yapıldı

2025-10-09 15:23:59,490 - DEBUG - Program başlatıldı
2025-10-09 15:24:05,592 - DEBUG - Programdan çıkış yapıldı

2025-10-09 15:24:12,786 - DEBUG - Program başlatıldı
2025-10-09 15:24:46,229 - DEBUG - Programdan çıkış yapıldı

2025-10-09 15:24:47,860 - DEBUG - Program başlatıldı
2025-10-09 15:24:50,680 - DEBUG - Programdan çıkış yapıldı

2025-10-09 15:25:29,612 - DEBUG - Program başlatıldı
2025-10-09 15:25:32,264 - DEBUG - Programdan çıkış yapıldı

2025-10-09 15:26:01,422 - DEBUG - Program başlatıldı
2025-10-09 15:26:09,798 - DEBUG - Programdan çıkış yapıldı

2025-10-09 15:27:08,217 - DEBUG - Program başlatıldı
2025-10-09 15:27:13,062 - DEBUG - Programdan çıkış yapıldı

2025-10-09 15:27:43,180 - DEBUG - Program başlatıldı
2025-10-09 15:27:46,130 - DEBUG - Programdan çıkış yapıldı

2025-10-09 15:28:10,816 - DEBUG - Program başlatıldı
2025-10-09 15:28:16,459 - DEBUG - Programdan çıkış yapıldı

2025-10-09 15:28:24,496 - DEBUG - Program başlatıldı
2025-10-09 15:28:28,146 - DEBUG - Programdan çıkış yapıldı

2025-10-09 15:36:24,565 - DEBUG - Program başlatıldı
2025-10-09 15:36:32,256 - DEBUG - Bir dosya seçildi --> /Users/tuakpina/Projects/PythonProjects/PyQt6/CsvToSql/table.csv
2025-10-09 15:36:33,796 - DEBUG - Çalıştır butonuna basıldı
2025-10-09 15:36:33,796 - DEBUG - Kullanıcı değerleri girmeden çalıştır butonuna bastı
2025-10-09 15:36:42,911 - DEBUG - Çalıştır butonuna basıldı
2025-10-09 15:36:45,448 - DEBUG - Programdan çıkış yapıldı

2025-10-09 15:36:49,771 - DEBUG - Program başlatıldı
2025-10-09 15:37:15,998 - DEBUG - Programdan çıkış yapıldı

2025-10-09 15:37:34,273 - DEBUG - Program başlatıldı
2025-10-09 15:37:41,946 - DEBUG - Programdan çıkış yapıldı

2025-10-09 15:43:06,243 - DEBUG - Program başlatıldı
2025-10-09 15:43:29,945 - DEBUG - Programdan çıkış yapıldı

2025-10-09 15:43:53,201 - DEBUG - Program başlatıldı
2025-10-09 15:43:58,208 - DEBUG - Çalıştır butonuna basıldı
2025-10-09 15:43:58,209 - DEBUG - Kullanıcı değerleri girmeden çalıştır butonuna bastı
2025-10-09 15:44:08,008 - DEBUG - Bir dosya seçildi --> /Users/tuakpina/Projects/PythonProjects/PyQt6/CsvToSql/table.csv
2025-10-09 15:44:13,843 - DEBUG - Çalıştır butonuna basıldı
2025-10-09 15:44:13,843 - DEBUG - Kullanıcı değerleri girmeden çalıştır butonuna bastı
2025-10-09 15:44:20,095 - DEBUG - Çalıştır butonuna basıldı
2025-10-09 15:44:22,078 - DEBUG - Programdan çıkış yapıldı

2025-10-09 15:45:24,494 - DEBUG - Program başlatıldı
2025-10-09 15:45:28,572 - DEBUG - Bir dosya seçildi --> /Users/tuakpina/Projects/PythonProjects/PyQt6/CsvToSql/table.csv
2025-10-09 15:45:39,293 - DEBUG - Çalıştır butonuna basıldı
2025-10-09 15:45:39,293 - DEBUG - Kullanıcı değerleri girmeden çalıştır butonuna bastı
2025-10-09 15:45:43,641 - DEBUG - Çalıştır butonuna basıldı
2025-10-09 15:45:54,678 - DEBUG - Programdan çıkış yapıldı

2025-10-09 16:08:36,025 - DEBUG - Program başlatıldı
2025-10-09 16:08:40,572 - DEBUG - Programdan çıkış yapıldı

2025-10-09 18:07:42,314 - DEBUG - Program başlatıldı
2025-10-09 18:07:48,452 - DEBUG - Bir dosya seçildi --> /Users/tuakpina/Projects/PythonProjects/PyQt6/CsvToSql/table.csv
2025-10-09 18:08:03,707 - DEBUG - Çalıştır butonuna basıldı
2025-10-09 18:08:25,737 - DEBUG - Çalıştır butonuna basıldı
2025-10-09 18:08:25,738 - DEBUG - Kullanıcı değerleri girmeden çalıştır butonuna bastı
2025-10-09 18:08:29,738 - DEBUG - Çalıştır butonuna basıldı
2025-10-09 18:08:34,566 - ERROR - run_buton: 1060 (42S21): Duplicate column name 'OrderID'
Traceback (most recent call last):
  File "/Library/Frameworks/Python.framework/Versions/3.13/lib/python3.13/site-packages/mysql/connector/connection_cext.py", line 772, in cmd_query
    self._cmysql.query(
    ~~~~~~~~~~~~~~~~~~^
        query,
        ^^^^^^
    ...<3 lines>...
        query_attrs=self.query_attrs,
        ^^^^^^^^^^^^^^^^^^^^^^^^^^^^^
    )
    ^
_mysql_connector.MySQLInterfaceError: Duplicate column name 'OrderID'

The above exception was the direct cause of the following exception:

Traceback (most recent call last):
  File "/Users/tuakpina/Projects/PythonProjects/PyQt6/CsvToSql/main.py", line 64, in run_button
    create_table(self.tablenametext)
    ~~~~~~~~~~~~^^^^^^^^^^^^^^^^^^^^
  File "/Users/tuakpina/Projects/PythonProjects/PyQt6/CsvToSql/behaviour.py", line 31, in __init__
    self.add_column()
    ~~~~~~~~~~~~~~~^^
  File "/Users/tuakpina/Projects/PythonProjects/PyQt6/CsvToSql/behaviour.py", line 42, in add_column
    self.cursor.execute(f"ALTER TABLE {self.table_name} ADD COLUMN {i} {self.int_value}")
    ~~~~~~~~~~~~~~~~~~~^^^^^^^^^^^^^^^^^^^^^^^^^^^^^^^^^^^^^^^^^^^^^^^^^^^^^^^^^^^^^^^^^^
  File "/Library/Frameworks/Python.framework/Versions/3.13/lib/python3.13/site-packages/mysql/connector/cursor_cext.py", line 353, in execute
    self._connection.cmd_query(
    ~~~~~~~~~~~~~~~~~~~~~~~~~~^
        self._stmt_partition["mappable_stmt"],
        ^^^^^^^^^^^^^^^^^^^^^^^^^^^^^^^^^^^^^^
    ...<2 lines>...
        raw_as_string=self._raw_as_string,
        ^^^^^^^^^^^^^^^^^^^^^^^^^^^^^^^^^^
    )
    ^
  File "/Library/Frameworks/Python.framework/Versions/3.13/lib/python3.13/site-packages/mysql/connector/opentelemetry/context_propagation.py", line 97, in wrapper
    return method(cnx, *args, **kwargs)
  File "/Library/Frameworks/Python.framework/Versions/3.13/lib/python3.13/site-packages/mysql/connector/connection_cext.py", line 781, in cmd_query
    raise get_mysql_exception(
        err.errno, msg=err.msg, sqlstate=err.sqlstate
    ) from err
mysql.connector.errors.ProgrammingError: 1060 (42S21): Duplicate column name 'OrderID'
2025-10-09 18:08:34,585 - DEBUG - Çalıştır butonuna basıldı
2025-10-09 18:08:37,603 - ERROR - run_buton: 1060 (42S21): Duplicate column name 'OrderID'
Traceback (most recent call last):
  File "/Library/Frameworks/Python.framework/Versions/3.13/lib/python3.13/site-packages/mysql/connector/connection_cext.py", line 772, in cmd_query
    self._cmysql.query(
    ~~~~~~~~~~~~~~~~~~^
        query,
        ^^^^^^
    ...<3 lines>...
        query_attrs=self.query_attrs,
        ^^^^^^^^^^^^^^^^^^^^^^^^^^^^^
    )
    ^
_mysql_connector.MySQLInterfaceError: Duplicate column name 'OrderID'

The above exception was the direct cause of the following exception:

Traceback (most recent call last):
  File "/Users/tuakpina/Projects/PythonProjects/PyQt6/CsvToSql/main.py", line 64, in run_button
    create_table(self.tablenametext)
    ~~~~~~~~~~~~^^^^^^^^^^^^^^^^^^^^
  File "/Users/tuakpina/Projects/PythonProjects/PyQt6/CsvToSql/behaviour.py", line 31, in __init__
    self.add_column()
    ~~~~~~~~~~~~~~~^^
  File "/Users/tuakpina/Projects/PythonProjects/PyQt6/CsvToSql/behaviour.py", line 42, in add_column
    self.cursor.execute(f"ALTER TABLE {self.table_name} ADD COLUMN {i} {self.int_value}")
    ~~~~~~~~~~~~~~~~~~~^^^^^^^^^^^^^^^^^^^^^^^^^^^^^^^^^^^^^^^^^^^^^^^^^^^^^^^^^^^^^^^^^^
  File "/Library/Frameworks/Python.framework/Versions/3.13/lib/python3.13/site-packages/mysql/connector/cursor_cext.py", line 353, in execute
    self._connection.cmd_query(
    ~~~~~~~~~~~~~~~~~~~~~~~~~~^
        self._stmt_partition["mappable_stmt"],
        ^^^^^^^^^^^^^^^^^^^^^^^^^^^^^^^^^^^^^^
    ...<2 lines>...
        raw_as_string=self._raw_as_string,
        ^^^^^^^^^^^^^^^^^^^^^^^^^^^^^^^^^^
    )
    ^
  File "/Library/Frameworks/Python.framework/Versions/3.13/lib/python3.13/site-packages/mysql/connector/opentelemetry/context_propagation.py", line 97, in wrapper
    return method(cnx, *args, **kwargs)
  File "/Library/Frameworks/Python.framework/Versions/3.13/lib/python3.13/site-packages/mysql/connector/connection_cext.py", line 781, in cmd_query
    raise get_mysql_exception(
        err.errno, msg=err.msg, sqlstate=err.sqlstate
    ) from err
mysql.connector.errors.ProgrammingError: 1060 (42S21): Duplicate column name 'OrderID'
2025-10-09 18:08:42,424 - DEBUG - Programdan çıkış yapıldı

2025-10-09 18:17:26,973 - DEBUG - Program başlatıldı
2025-10-09 18:17:34,811 - DEBUG - Bir dosya seçildi --> /Users/tuakpina/Projects/PythonProjects/PyQt6/CsvToSql/table.csv
2025-10-09 18:17:59,112 - DEBUG - Çalıştır butonuna basıldı
2025-10-09 18:19:55,979 - DEBUG - Programdan çıkış yapıldı

2025-10-09 18:20:13,327 - DEBUG - Program başlatıldı
2025-10-09 18:20:37,337 - DEBUG - Bir dosya seçildi --> /Users/tuakpina/Projects/PythonProjects/PyQt6/CsvToSql/table.csv
2025-10-09 18:20:47,142 - DEBUG - Çalıştır butonuna basıldı
2025-10-09 18:24:06,123 - DEBUG - Programdan çıkış yapıldı

2025-10-09 18:29:08,584 - DEBUG - Program başlatıldı
2025-10-09 18:29:21,123 - DEBUG - Bir dosya seçildi --> /Users/tuakpina/Projects/PythonProjects/PyQt6/CsvToSql/table.csv
2025-10-09 18:29:27,733 - DEBUG - Çalıştır butonuna basıldı
2025-10-09 18:29:31,253 - ERROR - run_buton: [Errno 2] No such file or directory: 'deneme'
Traceback (most recent call last):
  File "/Users/tuakpina/Projects/PythonProjects/PyQt6/CsvToSql/main.py", line 64, in run_button
    create_table(self.tablenametext)
    ~~~~~~~~~~~~^^^^^^^^^^^^^^^^^^^^
  File "/Users/tuakpina/Projects/PythonProjects/PyQt6/CsvToSql/behaviour.py", line 29, in __init__
    self.column.exec()
    ~~~~~~~~~~~~~~~~^^
  File "/Users/tuakpina/Projects/PythonProjects/PyQt6/CsvToSql/convert.py", line 9, in exec
    self.df = pd.read_csv(self.file_path, encoding="utf-8",delimiter=";")
              ~~~~~~~~~~~^^^^^^^^^^^^^^^^^^^^^^^^^^^^^^^^^^^^^^^^^^^^^^^^
  File "/Library/Frameworks/Python.framework/Versions/3.13/lib/python3.13/site-packages/pandas/io/parsers/readers.py", line 1026, in read_csv
    return _read(filepath_or_buffer, kwds)
  File "/Library/Frameworks/Python.framework/Versions/3.13/lib/python3.13/site-packages/pandas/io/parsers/readers.py", line 620, in _read
    parser = TextFileReader(filepath_or_buffer, **kwds)
  File "/Library/Frameworks/Python.framework/Versions/3.13/lib/python3.13/site-packages/pandas/io/parsers/readers.py", line 1620, in __init__
    self._engine = self._make_engine(f, self.engine)
                   ~~~~~~~~~~~~~~~~~^^^^^^^^^^^^^^^^
  File "/Library/Frameworks/Python.framework/Versions/3.13/lib/python3.13/site-packages/pandas/io/parsers/readers.py", line 1880, in _make_engine
    self.handles = get_handle(
                   ~~~~~~~~~~^
        f,
        ^^
    ...<6 lines>...
        storage_options=self.options.get("storage_options", None),
        ^^^^^^^^^^^^^^^^^^^^^^^^^^^^^^^^^^^^^^^^^^^^^^^^^^^^^^^^^^
    )
    ^
  File "/Library/Frameworks/Python.framework/Versions/3.13/lib/python3.13/site-packages/pandas/io/common.py", line 882, in get_handle
    handle = open(handle, ioargs.mode)
FileNotFoundError: [Errno 2] No such file or directory: 'deneme'
2025-10-09 18:30:42,652 - DEBUG - Programdan çıkış yapıldı

2025-10-09 18:32:45,507 - DEBUG - Program başlatıldı
2025-10-09 18:32:50,406 - DEBUG - Bir dosya seçildi --> /Users/tuakpina/Projects/PythonProjects/PyQt6/CsvToSql/table.csv
2025-10-09 18:32:58,213 - DEBUG - Çalıştır butonuna basıldı
2025-10-09 18:33:00,941 - ERROR - run_buton: 'create_table' object has no attribute 'column'
Traceback (most recent call last):
  File "/Users/tuakpina/Projects/PythonProjects/PyQt6/CsvToSql/main.py", line 64, in run_button
    create_table(self.tablenametext)
    ~~~~~~~~~~~~^^^^^^^^^^^^^^^^^^^^
  File "/Users/tuakpina/Projects/PythonProjects/PyQt6/CsvToSql/behaviour.py", line 28, in __init__
    self.column = self.column.df
                  ^^^^^^^^^^^
AttributeError: 'create_table' object has no attribute 'column'
2025-10-09 18:33:32,499 - DEBUG - Programdan çıkış yapıldı

2025-10-09 18:36:28,090 - DEBUG - Program başlatıldı
2025-10-09 18:36:32,463 - DEBUG - Programdan çıkış yapıldı

2025-10-09 18:36:48,796 - DEBUG - Program başlatıldı
2025-10-09 18:36:52,555 - DEBUG - Bir dosya seçildi --> /Users/tuakpina/Projects/PythonProjects/PyQt6/CsvToSql/table.csv
2025-10-09 18:37:02,376 - DEBUG - Çalıştır butonuna basıldı
2025-10-09 18:37:02,376 - ERROR - run_buton: convert.exec() missing 1 required positional argument: 'file_path'
Traceback (most recent call last):
  File "/Users/tuakpina/Projects/PythonProjects/PyQt6/CsvToSql/main.py", line 62, in run_button
    self.result = convert.exec(self.csv_path)
                  ~~~~~~~~~~~~^^^^^^^^^^^^^^^
TypeError: convert.exec() missing 1 required positional argument: 'file_path'
2025-10-09 18:37:27,663 - DEBUG - Programdan çıkış yapıldı

2025-10-09 18:39:46,256 - DEBUG - Program başlatıldı
2025-10-09 18:39:50,883 - DEBUG - Bir dosya seçildi --> /Users/tuakpina/Projects/PythonProjects/PyQt6/CsvToSql/table.csv
2025-10-09 18:40:02,256 - DEBUG - Çalıştır butonuna basıldı
2025-10-09 18:40:02,257 - ERROR - run_buton: convert.__init__() takes 1 positional argument but 2 were given
Traceback (most recent call last):
  File "/Users/tuakpina/Projects/PythonProjects/PyQt6/CsvToSql/main.py", line 62, in run_button
    self.result = convert(self.csv_path)
                  ~~~~~~~^^^^^^^^^^^^^^^
TypeError: convert.__init__() takes 1 positional argument but 2 were given
2025-10-09 18:40:32,908 - DEBUG - Programdan çıkış yapıldı

2025-10-09 18:40:34,877 - DEBUG - Program başlatıldı
2025-10-09 18:40:39,076 - DEBUG - Bir dosya seçildi --> /Users/tuakpina/Projects/PythonProjects/PyQt6/CsvToSql/table.csv
2025-10-09 18:40:51,553 - DEBUG - Çalıştır butonuna basıldı
2025-10-09 18:41:28,376 - DEBUG - Programdan çıkış yapıldı

2025-10-09 18:41:30,410 - DEBUG - Program başlatıldı
2025-10-09 18:41:38,738 - DEBUG - Bir dosya seçildi --> /Users/tuakpina/Projects/PythonProjects/PyQt6/CsvToSql/table.csv
2025-10-09 18:41:45,558 - DEBUG - Çalıştır butonuna basıldı
2025-10-09 18:42:10,976 - DEBUG - Programdan çıkış yapıldı

2025-10-09 18:44:48,944 - DEBUG - Program başlatıldı
2025-10-09 18:44:53,339 - DEBUG - Bir dosya seçildi --> /Users/tuakpina/Projects/PythonProjects/PyQt6/CsvToSql/table.csv
2025-10-09 18:45:01,273 - DEBUG - Çalıştır butonuna basıldı
2025-10-09 18:45:45,424 - DEBUG - Programdan çıkış yapıldı

2025-10-09 18:46:21,202 - DEBUG - Program başlatıldı
2025-10-09 18:46:22,724 - DEBUG - Programdan çıkış yapıldı

2025-10-09 18:53:30,217 - DEBUG - Program başlatıldı
2025-10-09 18:53:34,978 - DEBUG - Bir dosya seçildi --> /Users/tuakpina/Projects/PythonProjects/PyQt6/CsvToSql/table.csv
2025-10-09 18:53:40,516 - DEBUG - Çalıştır butonuna basıldı
2025-10-09 18:53:42,336 - ERROR - run_buton: Could not process parameters: int(10308), it must be of type list, tuple or dict
Traceback (most recent call last):
  File "/Users/tuakpina/Projects/PythonProjects/PyQt6/CsvToSql/main.py", line 64, in run_button
    create_table(self.tablenametext,self.result.df)
    ~~~~~~~~~~~~^^^^^^^^^^^^^^^^^^^^^^^^^^^^^^^^^^^
  File "/Users/tuakpina/Projects/PythonProjects/PyQt6/CsvToSql/behaviour.py", line 33, in __init__
    self.insert_user()
    ~~~~~~~~~~~~~~~~^^
  File "/Users/tuakpina/Projects/PythonProjects/PyQt6/CsvToSql/behaviour.py", line 53, in insert_user
    self.cursor.execute(insert_values,ex)
    ~~~~~~~~~~~~~~~~~~~^^^^^^^^^^^^^^^^^^
  File "/Library/Frameworks/Python.framework/Versions/3.13/lib/python3.13/site-packages/mysql/connector/cursor_cext.py", line 328, in execute
    prepared = self._connection.prepare_for_mysql(params)
  File "/Library/Frameworks/Python.framework/Versions/3.13/lib/python3.13/site-packages/mysql/connector/connection_cext.py", line 957, in prepare_for_mysql
    raise ProgrammingError(
    ...<2 lines>...
    )
mysql.connector.errors.ProgrammingError: Could not process parameters: int(10308), it must be of type list, tuple or dict
2025-10-09 18:55:24,284 - DEBUG - Programdan çıkış yapıldı

2025-10-09 18:55:25,928 - DEBUG - Program başlatıldı
2025-10-09 18:55:29,864 - DEBUG - Bir dosya seçildi --> /Users/tuakpina/Projects/PythonProjects/PyQt6/CsvToSql/table.csv
2025-10-09 18:55:39,263 - DEBUG - Çalıştır butonuna basıldı
2025-10-09 19:00:06,561 - DEBUG - Programdan çıkış yapıldı

2025-10-09 21:47:27,443 - DEBUG - Program başlatıldı
2025-10-09 21:47:29,944 - DEBUG - Programdan çıkış yapıldı

2025-10-09 22:14:08,082 - DEBUG - Program başlatıldı
2025-10-09 22:14:10,139 - DEBUG - Programdan çıkış yapıldı

2025-10-09 22:16:41,089 - DEBUG - Program başlatıldı
2025-10-09 22:16:42,571 - DEBUG - Programdan çıkış yapıldı

2025-10-09 22:38:56,754 - DEBUG - Program başlatıldı
2025-10-09 22:38:59,461 - DEBUG - Programdan çıkış yapıldı

2025-10-10 00:22:42,281 - DEBUG - Program başlatıldı
2025-10-10 00:22:53,132 - DEBUG - Programdan çıkış yapıldı

2025-10-10 02:11:54,593 - DEBUG - Program başlatıldı
2025-10-10 02:12:06,959 - DEBUG - Programdan çıkış yapıldı

2025-10-10 21:57:35,548 - DEBUG - Program başlatıldı
2025-10-10 21:57:39,719 - DEBUG - Bir dosya seçildi --> /Users/tuakpina/Projects/PythonProjects/PyQt6/CsvToSql/table.csv
2025-10-10 21:57:50,646 - DEBUG - Çalıştır butonuna basıldı
2025-10-10 22:00:53,598 - DEBUG - Programdan çıkış yapıldı

2025-10-10 22:00:55,126 - DEBUG - Program başlatıldı
2025-10-10 22:00:59,812 - DEBUG - Bir dosya seçildi --> /Users/tuakpina/Projects/PythonProjects/PyQt6/CsvToSql/table.csv
2025-10-10 22:01:07,363 - DEBUG - Çalıştır butonuna basıldı
2025-10-10 22:01:08,542 - ERROR - run_buton: 1060 (42S21): Duplicate column name 'OrderID'
Traceback (most recent call last):
  File "/Library/Frameworks/Python.framework/Versions/3.13/lib/python3.13/site-packages/mysql/connector/connection_cext.py", line 772, in cmd_query
    self._cmysql.query(
    ~~~~~~~~~~~~~~~~~~^
        query,
        ^^^^^^
    ...<3 lines>...
        query_attrs=self.query_attrs,
        ^^^^^^^^^^^^^^^^^^^^^^^^^^^^^
    )
    ^
_mysql_connector.MySQLInterfaceError: Duplicate column name 'OrderID'

The above exception was the direct cause of the following exception:

Traceback (most recent call last):
  File "/Users/tuakpina/Projects/PythonProjects/PyQt6/CsvToSql/main.py", line 64, in run_button
    create_table(self.tablenametext,self.result.df)
    ~~~~~~~~~~~~^^^^^^^^^^^^^^^^^^^^^^^^^^^^^^^^^^^
  File "/Users/tuakpina/Projects/PythonProjects/PyQt6/CsvToSql/behaviour.py", line 33, in __init__
    self.add_column()
    ~~~~~~~~~~~~~~~^^
  File "/Users/tuakpina/Projects/PythonProjects/PyQt6/CsvToSql/behaviour.py", line 43, in add_column
    self.cursor.execute(f"ALTER TABLE {self.table_name} ADD COLUMN {i} {self.int_value}")
    ~~~~~~~~~~~~~~~~~~~^^^^^^^^^^^^^^^^^^^^^^^^^^^^^^^^^^^^^^^^^^^^^^^^^^^^^^^^^^^^^^^^^^
  File "/Library/Frameworks/Python.framework/Versions/3.13/lib/python3.13/site-packages/mysql/connector/cursor_cext.py", line 353, in execute
    self._connection.cmd_query(
    ~~~~~~~~~~~~~~~~~~~~~~~~~~^
        self._stmt_partition["mappable_stmt"],
        ^^^^^^^^^^^^^^^^^^^^^^^^^^^^^^^^^^^^^^
    ...<2 lines>...
        raw_as_string=self._raw_as_string,
        ^^^^^^^^^^^^^^^^^^^^^^^^^^^^^^^^^^
    )
    ^
  File "/Library/Frameworks/Python.framework/Versions/3.13/lib/python3.13/site-packages/mysql/connector/opentelemetry/context_propagation.py", line 97, in wrapper
    return method(cnx, *args, **kwargs)
  File "/Library/Frameworks/Python.framework/Versions/3.13/lib/python3.13/site-packages/mysql/connector/connection_cext.py", line 781, in cmd_query
    raise get_mysql_exception(
        err.errno, msg=err.msg, sqlstate=err.sqlstate
    ) from err
mysql.connector.errors.ProgrammingError: 1060 (42S21): Duplicate column name 'OrderID'
2025-10-10 22:01:50,030 - DEBUG - Çalıştır butonuna basıldı
2025-10-10 22:01:51,560 - ERROR - run_buton: 1064 (42000): You have an error in your SQL syntax; check the manual that corresponds to your MySQL server version for the right syntax to use near '[10308, 'Ana Trujillo Emparedados y helados', '9/18/1996'])' at line 1
Traceback (most recent call last):
  File "/Library/Frameworks/Python.framework/Versions/3.13/lib/python3.13/site-packages/mysql/connector/connection_cext.py", line 772, in cmd_query
    self._cmysql.query(
    ~~~~~~~~~~~~~~~~~~^
        query,
        ^^^^^^
    ...<3 lines>...
        query_attrs=self.query_attrs,
        ^^^^^^^^^^^^^^^^^^^^^^^^^^^^^
    )
    ^
_mysql_connector.MySQLInterfaceError: You have an error in your SQL syntax; check the manual that corresponds to your MySQL server version for the right syntax to use near '[10308, 'Ana Trujillo Emparedados y helados', '9/18/1996'])' at line 1

The above exception was the direct cause of the following exception:

Traceback (most recent call last):
  File "/Users/tuakpina/Projects/PythonProjects/PyQt6/CsvToSql/main.py", line 64, in run_button
    create_table(self.tablenametext,self.result.df)
    ~~~~~~~~~~~~^^^^^^^^^^^^^^^^^^^^^^^^^^^^^^^^^^^
  File "/Users/tuakpina/Projects/PythonProjects/PyQt6/CsvToSql/behaviour.py", line 34, in __init__
    self.insert_user()
    ~~~~~~~~~~~~~~~~^^
  File "/Users/tuakpina/Projects/PythonProjects/PyQt6/CsvToSql/behaviour.py", line 53, in insert_user
    self.cursor.execute(f"INSERT INTO {self.table_name} ({birlestir}) VALUES ({self.liste[0:3]})")
    ~~~~~~~~~~~~~~~~~~~^^^^^^^^^^^^^^^^^^^^^^^^^^^^^^^^^^^^^^^^^^^^^^^^^^^^^^^^^^^^^^^^^^^^^^^^^^^
  File "/Library/Frameworks/Python.framework/Versions/3.13/lib/python3.13/site-packages/mysql/connector/cursor_cext.py", line 353, in execute
    self._connection.cmd_query(
    ~~~~~~~~~~~~~~~~~~~~~~~~~~^
        self._stmt_partition["mappable_stmt"],
        ^^^^^^^^^^^^^^^^^^^^^^^^^^^^^^^^^^^^^^
    ...<2 lines>...
        raw_as_string=self._raw_as_string,
        ^^^^^^^^^^^^^^^^^^^^^^^^^^^^^^^^^^
    )
    ^
  File "/Library/Frameworks/Python.framework/Versions/3.13/lib/python3.13/site-packages/mysql/connector/opentelemetry/context_propagation.py", line 97, in wrapper
    return method(cnx, *args, **kwargs)
  File "/Library/Frameworks/Python.framework/Versions/3.13/lib/python3.13/site-packages/mysql/connector/connection_cext.py", line 781, in cmd_query
    raise get_mysql_exception(
        err.errno, msg=err.msg, sqlstate=err.sqlstate
    ) from err
mysql.connector.errors.ProgrammingError: 1064 (42000): You have an error in your SQL syntax; check the manual that corresponds to your MySQL server version for the right syntax to use near '[10308, 'Ana Trujillo Emparedados y helados', '9/18/1996'])' at line 1
2025-10-10 22:08:45,872 - DEBUG - Programdan çıkış yapıldı

2025-10-10 22:15:16,029 - DEBUG - Program başlatıldı
2025-10-10 22:15:21,022 - DEBUG - Bir dosya seçildi --> /Users/tuakpina/Projects/PythonProjects/PyQt6/CsvToSql/table.csv
2025-10-10 22:15:27,238 - DEBUG - Çalıştır butonuna basıldı
2025-10-10 22:39:35,285 - DEBUG - Programdan çıkış yapıldı

2025-10-10 22:39:45,079 - DEBUG - Program başlatıldı
2025-10-10 22:39:56,904 - DEBUG - Bir dosya seçildi --> 
2025-10-10 22:45:57,190 - DEBUG - Bir dosya seçildi --> 
2025-10-10 22:46:09,750 - DEBUG - Bir dosya seçildi --> /Users/tuakpina/Projects/PythonProjects/PyQt6/CsvToSql/table_1.csv
2025-10-10 22:46:18,855 - DEBUG - Çalıştır butonuna basıldı
2025-10-10 22:46:19,870 - ERROR - run_buton: 1064 (42000): You have an error in your SQL syntax; check the manual that corresponds to your MySQL server version for the right syntax to use near 'table (
    id INT AUTO_INCREMENT PRIMARY KEY
)' at line 1
Traceback (most recent call last):
  File "/Library/Frameworks/Python.framework/Versions/3.13/lib/python3.13/site-packages/mysql/connector/connection_cext.py", line 772, in cmd_query
    self._cmysql.query(
    ~~~~~~~~~~~~~~~~~~^
        query,
        ^^^^^^
    ...<3 lines>...
        query_attrs=self.query_attrs,
        ^^^^^^^^^^^^^^^^^^^^^^^^^^^^^
    )
    ^
_mysql_connector.MySQLInterfaceError: You have an error in your SQL syntax; check the manual that corresponds to your MySQL server version for the right syntax to use near 'table (
    id INT AUTO_INCREMENT PRIMARY KEY
)' at line 1

The above exception was the direct cause of the following exception:

Traceback (most recent call last):
  File "/Users/tuakpina/Projects/PythonProjects/PyQt6/CsvToSql/main.py", line 64, in run_button
    create_table(self.tablenametext,self.result.df)
    ~~~~~~~~~~~~^^^^^^^^^^^^^^^^^^^^^^^^^^^^^^^^^^^
  File "/Users/tuakpina/Projects/PythonProjects/PyQt6/CsvToSql/behaviour.py", line 27, in __init__
                self.cursor.execute(f"""
                ~~~~~~~~~~~~~~~~~~~^^^^^
    CREATE TABLE IF NOT EXISTS {table_name} (
    ^^^^^^^^^^^^^^^^^^^^^^^^^^^^^^^^^^^^^^^^^
        id INT AUTO_INCREMENT PRIMARY KEY
        ^^^^^^^^^^^^^^^^^^^^^^^^^^^^^^^^^
    )
    ^
    """)
    ^^^^
  File "/Library/Frameworks/Python.framework/Versions/3.13/lib/python3.13/site-packages/mysql/connector/cursor_cext.py", line 353, in execute
    self._connection.cmd_query(
    ~~~~~~~~~~~~~~~~~~~~~~~~~~^
        self._stmt_partition["mappable_stmt"],
        ^^^^^^^^^^^^^^^^^^^^^^^^^^^^^^^^^^^^^^
    ...<2 lines>...
        raw_as_string=self._raw_as_string,
        ^^^^^^^^^^^^^^^^^^^^^^^^^^^^^^^^^^
    )
    ^
  File "/Library/Frameworks/Python.framework/Versions/3.13/lib/python3.13/site-packages/mysql/connector/opentelemetry/context_propagation.py", line 97, in wrapper
    return method(cnx, *args, **kwargs)
  File "/Library/Frameworks/Python.framework/Versions/3.13/lib/python3.13/site-packages/mysql/connector/connection_cext.py", line 781, in cmd_query
    raise get_mysql_exception(
        err.errno, msg=err.msg, sqlstate=err.sqlstate
    ) from err
mysql.connector.errors.ProgrammingError: 1064 (42000): You have an error in your SQL syntax; check the manual that corresponds to your MySQL server version for the right syntax to use near 'table (
    id INT AUTO_INCREMENT PRIMARY KEY
)' at line 1
2025-10-10 22:47:19,840 - DEBUG - Çalıştır butonuna basıldı
2025-10-10 22:48:22,841 - DEBUG - Programdan çıkış yapıldı

2025-10-10 23:02:25,860 - DEBUG - Program başlatıldı
2025-10-10 23:03:19,074 - DEBUG - Bir dosya seçildi --> /Users/tuakpina/Projects/PythonProjects/PyQt6/CsvToSql/table_1.csv
2025-10-10 23:03:29,898 - DEBUG - Çalıştır butonuna basıldı
2025-10-10 23:03:31,476 - ERROR - run_buton: 1054 (42S22): Unknown column 'Fiyat' in 'field list'
Traceback (most recent call last):
  File "/Library/Frameworks/Python.framework/Versions/3.13/lib/python3.13/site-packages/mysql/connector/connection_cext.py", line 772, in cmd_query
    self._cmysql.query(
    ~~~~~~~~~~~~~~~~~~^
        query,
        ^^^^^^
    ...<3 lines>...
        query_attrs=self.query_attrs,
        ^^^^^^^^^^^^^^^^^^^^^^^^^^^^^
    )
    ^
_mysql_connector.MySQLInterfaceError: Unknown column 'Fiyat' in 'field list'

The above exception was the direct cause of the following exception:

Traceback (most recent call last):
  File "/Users/tuakpina/Projects/PythonProjects/PyQt6/CsvToSql/main.py", line 64, in run_button
    create_table(self.tablenametext,self.result.df)
    ~~~~~~~~~~~~^^^^^^^^^^^^^^^^^^^^^^^^^^^^^^^^^^^
  File "/Users/tuakpina/Projects/PythonProjects/PyQt6/CsvToSql/behaviour.py", line 34, in __init__
    self.insert_user()
    ~~~~~~~~~~~~~~~~^^
  File "/Users/tuakpina/Projects/PythonProjects/PyQt6/CsvToSql/behaviour.py", line 56, in insert_user
    self.cursor.execute(sql_insert,values)
    ~~~~~~~~~~~~~~~~~~~^^^^^^^^^^^^^^^^^^^
  File "/Library/Frameworks/Python.framework/Versions/3.13/lib/python3.13/site-packages/mysql/connector/cursor_cext.py", line 353, in execute
    self._connection.cmd_query(
    ~~~~~~~~~~~~~~~~~~~~~~~~~~^
        self._stmt_partition["mappable_stmt"],
        ^^^^^^^^^^^^^^^^^^^^^^^^^^^^^^^^^^^^^^
    ...<2 lines>...
        raw_as_string=self._raw_as_string,
        ^^^^^^^^^^^^^^^^^^^^^^^^^^^^^^^^^^
    )
    ^
  File "/Library/Frameworks/Python.framework/Versions/3.13/lib/python3.13/site-packages/mysql/connector/opentelemetry/context_propagation.py", line 97, in wrapper
    return method(cnx, *args, **kwargs)
  File "/Library/Frameworks/Python.framework/Versions/3.13/lib/python3.13/site-packages/mysql/connector/connection_cext.py", line 781, in cmd_query
    raise get_mysql_exception(
        err.errno, msg=err.msg, sqlstate=err.sqlstate
    ) from err
mysql.connector.errors.ProgrammingError: 1054 (42S22): Unknown column 'Fiyat' in 'field list'
2025-10-10 23:06:06,952 - DEBUG - Programdan çıkış yapıldı

2025-10-10 23:07:13,908 - DEBUG - Program başlatıldı
2025-10-10 23:07:18,636 - DEBUG - Bir dosya seçildi --> /Users/tuakpina/Projects/PythonProjects/PyQt6/CsvToSql/table_1.csv
2025-10-10 23:07:35,399 - DEBUG - Çalıştır butonuna basıldı
2025-10-10 23:09:16,569 - DEBUG - Programdan çıkış yapıldı

2025-10-10 23:09:34,607 - DEBUG - Program başlatıldı
2025-10-10 23:09:40,358 - DEBUG - Bir dosya seçildi --> /Users/tuakpina/Projects/PythonProjects/PyQt6/CsvToSql/table_1.csv
2025-10-10 23:09:53,299 - DEBUG - Çalıştır butonuna basıldı
2025-10-10 23:21:30,765 - DEBUG - Programdan çıkış yapıldı

2025-10-11 16:04:38,261 - DEBUG - Program başlatıldı
2025-10-11 16:07:19,739 - DEBUG - Programdan çıkış yapıldı

2025-10-12 19:32:23,617 - DEBUG - Program başlatıldı
2025-10-12 19:32:41,944 - DEBUG - Bir dosya seçildi --> /Users/tuakpina/Projects/PythonProjects/PyQt6/CsvToSql/table_1.csv
2025-10-12 19:33:01,822 - DEBUG - Çalıştır butonuna basıldı
2025-10-12 19:34:07,720 - DEBUG - Programdan çıkış yapıldı

2025-10-13 11:21:49,351 - DEBUG - Program başlatıldı
2025-10-13 11:21:51,313 - DEBUG - Programdan çıkış yapıldı

2025-10-14 12:31:40,345 - DEBUG - Program başlatıldı
2025-10-14 12:31:49,063 - DEBUG - Bir dosya seçildi --> /Users/tuakpina/Projects/PythonProjects/PyQt6/CsvToSql/table_1.csv
2025-10-14 12:31:59,002 - DEBUG - Çalıştır butonuna basıldı
2025-10-14 12:34:37,442 - DEBUG - Bir dosya seçildi --> /Users/tuakpina/Projects/PythonProjects/PyQt6/CsvToSql/rastgele_veri.csv
2025-10-14 12:34:41,319 - DEBUG - Çalıştır butonuna basıldı
2025-10-14 12:34:42,972 - ERROR - run_buton: 1064 (42000): You have an error in your SQL syntax; check the manual that corresponds to your MySQL server version for the right syntax to use near ',isim,soyisim,email,telefon,şehir,yaş,kayıt_tarihi,puan VARCHAR(50)' at line 1
Traceback (most recent call last):
  File "/Library/Frameworks/Python.framework/Versions/3.13/lib/python3.13/site-packages/mysql/connector/connection_cext.py", line 772, in cmd_query
    self._cmysql.query(
    ~~~~~~~~~~~~~~~~~~^
        query,
        ^^^^^^
    ...<3 lines>...
        query_attrs=self.query_attrs,
        ^^^^^^^^^^^^^^^^^^^^^^^^^^^^^
    )
    ^
_mysql_connector.MySQLInterfaceError: You have an error in your SQL syntax; check the manual that corresponds to your MySQL server version for the right syntax to use near ',isim,soyisim,email,telefon,şehir,yaş,kayıt_tarihi,puan VARCHAR(50)' at line 1

The above exception was the direct cause of the following exception:

Traceback (most recent call last):
  File "/Users/tuakpina/Projects/PythonProjects/PyQt6/CsvToSql/main.py", line 64, in run_button
    create_table(self.tablenametext,self.result.df)
    ~~~~~~~~~~~~^^^^^^^^^^^^^^^^^^^^^^^^^^^^^^^^^^^
  File "/Users/tuakpina/Projects/PythonProjects/PyQt6/CsvToSql/behaviour.py", line 35, in __init__
    self.add_column()
    ~~~~~~~~~~~~~~~^^
  File "/Users/tuakpina/Projects/PythonProjects/PyQt6/CsvToSql/behaviour.py", line 47, in add_column
    self.cursor.execute(f"ALTER TABLE {self.table_name} ADD COLUMN {i} {self.varchar}")
    ~~~~~~~~~~~~~~~~~~~^^^^^^^^^^^^^^^^^^^^^^^^^^^^^^^^^^^^^^^^^^^^^^^^^^^^^^^^^^^^^^^^
  File "/Library/Frameworks/Python.framework/Versions/3.13/lib/python3.13/site-packages/mysql/connector/cursor_cext.py", line 353, in execute
    self._connection.cmd_query(
    ~~~~~~~~~~~~~~~~~~~~~~~~~~^
        self._stmt_partition["mappable_stmt"],
        ^^^^^^^^^^^^^^^^^^^^^^^^^^^^^^^^^^^^^^
    ...<2 lines>...
        raw_as_string=self._raw_as_string,
        ^^^^^^^^^^^^^^^^^^^^^^^^^^^^^^^^^^
    )
    ^
  File "/Library/Frameworks/Python.framework/Versions/3.13/lib/python3.13/site-packages/mysql/connector/opentelemetry/context_propagation.py", line 97, in wrapper
    return method(cnx, *args, **kwargs)
  File "/Library/Frameworks/Python.framework/Versions/3.13/lib/python3.13/site-packages/mysql/connector/connection_cext.py", line 781, in cmd_query
    raise get_mysql_exception(
        err.errno, msg=err.msg, sqlstate=err.sqlstate
    ) from err
mysql.connector.errors.ProgrammingError: 1064 (42000): You have an error in your SQL syntax; check the manual that corresponds to your MySQL server version for the right syntax to use near ',isim,soyisim,email,telefon,şehir,yaş,kayıt_tarihi,puan VARCHAR(50)' at line 1
2025-10-14 12:35:10,040 - DEBUG - Programdan çıkış yapıldı

2025-10-14 12:35:13,565 - DEBUG - Program başlatıldı
2025-10-14 12:35:17,898 - DEBUG - Bir dosya seçildi --> /Users/tuakpina/Projects/PythonProjects/PyQt6/CsvToSql/rastgele_veri.csv
2025-10-14 12:35:28,888 - DEBUG - Çalıştır butonuna basıldı
2025-10-14 12:35:30,267 - ERROR - run_buton: 1064 (42000): You have an error in your SQL syntax; check the manual that corresponds to your MySQL server version for the right syntax to use near ',isim,soyisim,email,telefon,şehir,yaş,kayıt_tarihi,puan VARCHAR(255)' at line 1
Traceback (most recent call last):
  File "/Library/Frameworks/Python.framework/Versions/3.13/lib/python3.13/site-packages/mysql/connector/connection_cext.py", line 772, in cmd_query
    self._cmysql.query(
    ~~~~~~~~~~~~~~~~~~^
        query,
        ^^^^^^
    ...<3 lines>...
        query_attrs=self.query_attrs,
        ^^^^^^^^^^^^^^^^^^^^^^^^^^^^^
    )
    ^
_mysql_connector.MySQLInterfaceError: You have an error in your SQL syntax; check the manual that corresponds to your MySQL server version for the right syntax to use near ',isim,soyisim,email,telefon,şehir,yaş,kayıt_tarihi,puan VARCHAR(255)' at line 1

The above exception was the direct cause of the following exception:

Traceback (most recent call last):
  File "/Users/tuakpina/Projects/PythonProjects/PyQt6/CsvToSql/main.py", line 64, in run_button
    create_table(self.tablenametext,self.result.df)
    ~~~~~~~~~~~~^^^^^^^^^^^^^^^^^^^^^^^^^^^^^^^^^^^
  File "/Users/tuakpina/Projects/PythonProjects/PyQt6/CsvToSql/behaviour.py", line 35, in __init__
    self.add_column()
    ~~~~~~~~~~~~~~~^^
  File "/Users/tuakpina/Projects/PythonProjects/PyQt6/CsvToSql/behaviour.py", line 47, in add_column
    self.cursor.execute(f"ALTER TABLE {self.table_name} ADD COLUMN {i} {self.varchar}")
    ~~~~~~~~~~~~~~~~~~~^^^^^^^^^^^^^^^^^^^^^^^^^^^^^^^^^^^^^^^^^^^^^^^^^^^^^^^^^^^^^^^^
  File "/Library/Frameworks/Python.framework/Versions/3.13/lib/python3.13/site-packages/mysql/connector/cursor_cext.py", line 353, in execute
    self._connection.cmd_query(
    ~~~~~~~~~~~~~~~~~~~~~~~~~~^
        self._stmt_partition["mappable_stmt"],
        ^^^^^^^^^^^^^^^^^^^^^^^^^^^^^^^^^^^^^^
    ...<2 lines>...
        raw_as_string=self._raw_as_string,
        ^^^^^^^^^^^^^^^^^^^^^^^^^^^^^^^^^^
    )
    ^
  File "/Library/Frameworks/Python.framework/Versions/3.13/lib/python3.13/site-packages/mysql/connector/opentelemetry/context_propagation.py", line 97, in wrapper
    return method(cnx, *args, **kwargs)
  File "/Library/Frameworks/Python.framework/Versions/3.13/lib/python3.13/site-packages/mysql/connector/connection_cext.py", line 781, in cmd_query
    raise get_mysql_exception(
        err.errno, msg=err.msg, sqlstate=err.sqlstate
    ) from err
mysql.connector.errors.ProgrammingError: 1064 (42000): You have an error in your SQL syntax; check the manual that corresponds to your MySQL server version for the right syntax to use near ',isim,soyisim,email,telefon,şehir,yaş,kayıt_tarihi,puan VARCHAR(255)' at line 1
2025-10-14 12:36:13,754 - DEBUG - Programdan çıkış yapıldı

2025-10-14 12:37:26,728 - DEBUG - Program başlatıldı
2025-10-14 12:37:31,110 - DEBUG - Bir dosya seçildi --> /Users/tuakpina/Projects/PythonProjects/PyQt6/CsvToSql/rastgele_veri.csv
2025-10-14 12:37:38,169 - DEBUG - Çalıştır butonuna basıldı
2025-10-14 12:38:02,585 - DEBUG - Çalıştır butonuna basıldı
2025-10-14 12:38:21,679 - DEBUG - Programdan çıkış yapıldı

2025-10-14 12:38:23,533 - DEBUG - Program başlatıldı
2025-10-14 12:38:29,386 - DEBUG - Bir dosya seçildi --> /Users/tuakpina/Projects/PythonProjects/PyQt6/CsvToSql/rastgele_veri.csv
2025-10-14 12:38:34,744 - DEBUG - Çalıştır butonuna basıldı
2025-10-14 12:38:49,277 - DEBUG - Çalıştır butonuna basıldı
2025-10-14 12:39:59,476 - DEBUG - Çalıştır butonuna basıldı
2025-10-14 12:40:25,327 - DEBUG - Programdan çıkış yapıldı

2025-10-14 12:40:54,771 - DEBUG - Program başlatıldı
2025-10-14 12:40:59,919 - DEBUG - Bir dosya seçildi --> /Users/tuakpina/Projects/PythonProjects/PyQt6/CsvToSql/rastgele_veri.csv
2025-10-14 12:41:11,674 - DEBUG - Çalıştır butonuna basıldı
2025-10-14 12:41:13,003 - ERROR - run_buton: 1060 (42S21): Duplicate column name 'id'
Traceback (most recent call last):
  File "/Library/Frameworks/Python.framework/Versions/3.13/lib/python3.13/site-packages/mysql/connector/connection_cext.py", line 772, in cmd_query
    self._cmysql.query(
    ~~~~~~~~~~~~~~~~~~^
        query,
        ^^^^^^
    ...<3 lines>...
        query_attrs=self.query_attrs,
        ^^^^^^^^^^^^^^^^^^^^^^^^^^^^^
    )
    ^
_mysql_connector.MySQLInterfaceError: Duplicate column name 'id'

The above exception was the direct cause of the following exception:

Traceback (most recent call last):
  File "/Users/tuakpina/Projects/PythonProjects/PyQt6/CsvToSql/main.py", line 64, in run_button
    create_table(self.tablenametext,self.result.df)
    ~~~~~~~~~~~~^^^^^^^^^^^^^^^^^^^^^^^^^^^^^^^^^^^
  File "/Users/tuakpina/Projects/PythonProjects/PyQt6/CsvToSql/behaviour.py", line 35, in __init__
    self.add_column()
    ~~~~~~~~~~~~~~~^^
  File "/Users/tuakpina/Projects/PythonProjects/PyQt6/CsvToSql/behaviour.py", line 45, in add_column
    self.cursor.execute(f"ALTER TABLE {self.table_name} ADD COLUMN {i} {self.int_value}")
    ~~~~~~~~~~~~~~~~~~~^^^^^^^^^^^^^^^^^^^^^^^^^^^^^^^^^^^^^^^^^^^^^^^^^^^^^^^^^^^^^^^^^^
  File "/Library/Frameworks/Python.framework/Versions/3.13/lib/python3.13/site-packages/mysql/connector/cursor_cext.py", line 353, in execute
    self._connection.cmd_query(
    ~~~~~~~~~~~~~~~~~~~~~~~~~~^
        self._stmt_partition["mappable_stmt"],
        ^^^^^^^^^^^^^^^^^^^^^^^^^^^^^^^^^^^^^^
    ...<2 lines>...
        raw_as_string=self._raw_as_string,
        ^^^^^^^^^^^^^^^^^^^^^^^^^^^^^^^^^^
    )
    ^
  File "/Library/Frameworks/Python.framework/Versions/3.13/lib/python3.13/site-packages/mysql/connector/opentelemetry/context_propagation.py", line 97, in wrapper
    return method(cnx, *args, **kwargs)
  File "/Library/Frameworks/Python.framework/Versions/3.13/lib/python3.13/site-packages/mysql/connector/connection_cext.py", line 781, in cmd_query
    raise get_mysql_exception(
        err.errno, msg=err.msg, sqlstate=err.sqlstate
    ) from err
mysql.connector.errors.ProgrammingError: 1060 (42S21): Duplicate column name 'id'
2025-10-14 12:41:33,124 - DEBUG - Çalıştır butonuna basıldı
2025-10-14 12:41:34,362 - ERROR - run_buton: 1060 (42S21): Duplicate column name 'id'
Traceback (most recent call last):
  File "/Library/Frameworks/Python.framework/Versions/3.13/lib/python3.13/site-packages/mysql/connector/connection_cext.py", line 772, in cmd_query
    self._cmysql.query(
    ~~~~~~~~~~~~~~~~~~^
        query,
        ^^^^^^
    ...<3 lines>...
        query_attrs=self.query_attrs,
        ^^^^^^^^^^^^^^^^^^^^^^^^^^^^^
    )
    ^
_mysql_connector.MySQLInterfaceError: Duplicate column name 'id'

The above exception was the direct cause of the following exception:

Traceback (most recent call last):
  File "/Users/tuakpina/Projects/PythonProjects/PyQt6/CsvToSql/main.py", line 64, in run_button
    create_table(self.tablenametext,self.result.df)
    ~~~~~~~~~~~~^^^^^^^^^^^^^^^^^^^^^^^^^^^^^^^^^^^
  File "/Users/tuakpina/Projects/PythonProjects/PyQt6/CsvToSql/behaviour.py", line 35, in __init__
    self.add_column()
    ~~~~~~~~~~~~~~~^^
  File "/Users/tuakpina/Projects/PythonProjects/PyQt6/CsvToSql/behaviour.py", line 45, in add_column
    self.cursor.execute(f"ALTER TABLE {self.table_name} ADD COLUMN {i} {self.int_value}")
    ~~~~~~~~~~~~~~~~~~~^^^^^^^^^^^^^^^^^^^^^^^^^^^^^^^^^^^^^^^^^^^^^^^^^^^^^^^^^^^^^^^^^^
  File "/Library/Frameworks/Python.framework/Versions/3.13/lib/python3.13/site-packages/mysql/connector/cursor_cext.py", line 353, in execute
    self._connection.cmd_query(
    ~~~~~~~~~~~~~~~~~~~~~~~~~~^
        self._stmt_partition["mappable_stmt"],
        ^^^^^^^^^^^^^^^^^^^^^^^^^^^^^^^^^^^^^^
    ...<2 lines>...
        raw_as_string=self._raw_as_string,
        ^^^^^^^^^^^^^^^^^^^^^^^^^^^^^^^^^^
    )
    ^
  File "/Library/Frameworks/Python.framework/Versions/3.13/lib/python3.13/site-packages/mysql/connector/opentelemetry/context_propagation.py", line 97, in wrapper
    return method(cnx, *args, **kwargs)
  File "/Library/Frameworks/Python.framework/Versions/3.13/lib/python3.13/site-packages/mysql/connector/connection_cext.py", line 781, in cmd_query
    raise get_mysql_exception(
        err.errno, msg=err.msg, sqlstate=err.sqlstate
    ) from err
mysql.connector.errors.ProgrammingError: 1060 (42S21): Duplicate column name 'id'
2025-10-14 12:41:40,258 - DEBUG - Çalıştır butonuna basıldı
2025-10-14 12:41:41,562 - ERROR - run_buton: 1060 (42S21): Duplicate column name 'id'
Traceback (most recent call last):
  File "/Library/Frameworks/Python.framework/Versions/3.13/lib/python3.13/site-packages/mysql/connector/connection_cext.py", line 772, in cmd_query
    self._cmysql.query(
    ~~~~~~~~~~~~~~~~~~^
        query,
        ^^^^^^
    ...<3 lines>...
        query_attrs=self.query_attrs,
        ^^^^^^^^^^^^^^^^^^^^^^^^^^^^^
    )
    ^
_mysql_connector.MySQLInterfaceError: Duplicate column name 'id'

The above exception was the direct cause of the following exception:

Traceback (most recent call last):
  File "/Users/tuakpina/Projects/PythonProjects/PyQt6/CsvToSql/main.py", line 64, in run_button
    create_table(self.tablenametext,self.result.df)
    ~~~~~~~~~~~~^^^^^^^^^^^^^^^^^^^^^^^^^^^^^^^^^^^
  File "/Users/tuakpina/Projects/PythonProjects/PyQt6/CsvToSql/behaviour.py", line 35, in __init__
    self.add_column()
    ~~~~~~~~~~~~~~~^^
  File "/Users/tuakpina/Projects/PythonProjects/PyQt6/CsvToSql/behaviour.py", line 45, in add_column
    self.cursor.execute(f"ALTER TABLE {self.table_name} ADD COLUMN {i} {self.int_value}")
    ~~~~~~~~~~~~~~~~~~~^^^^^^^^^^^^^^^^^^^^^^^^^^^^^^^^^^^^^^^^^^^^^^^^^^^^^^^^^^^^^^^^^^
  File "/Library/Frameworks/Python.framework/Versions/3.13/lib/python3.13/site-packages/mysql/connector/cursor_cext.py", line 353, in execute
    self._connection.cmd_query(
    ~~~~~~~~~~~~~~~~~~~~~~~~~~^
        self._stmt_partition["mappable_stmt"],
        ^^^^^^^^^^^^^^^^^^^^^^^^^^^^^^^^^^^^^^
    ...<2 lines>...
        raw_as_string=self._raw_as_string,
        ^^^^^^^^^^^^^^^^^^^^^^^^^^^^^^^^^^
    )
    ^
  File "/Library/Frameworks/Python.framework/Versions/3.13/lib/python3.13/site-packages/mysql/connector/opentelemetry/context_propagation.py", line 97, in wrapper
    return method(cnx, *args, **kwargs)
  File "/Library/Frameworks/Python.framework/Versions/3.13/lib/python3.13/site-packages/mysql/connector/connection_cext.py", line 781, in cmd_query
    raise get_mysql_exception(
        err.errno, msg=err.msg, sqlstate=err.sqlstate
    ) from err
mysql.connector.errors.ProgrammingError: 1060 (42S21): Duplicate column name 'id'
2025-10-14 12:45:27,040 - DEBUG - Çalıştır butonuna basıldı
2025-10-14 12:47:29,270 - DEBUG - Çalıştır butonuna basıldı
2025-10-14 12:47:30,646 - ERROR - run_buton: 1060 (42S21): Duplicate column name 'isim'
Traceback (most recent call last):
  File "/Library/Frameworks/Python.framework/Versions/3.13/lib/python3.13/site-packages/mysql/connector/connection_cext.py", line 772, in cmd_query
    self._cmysql.query(
    ~~~~~~~~~~~~~~~~~~^
        query,
        ^^^^^^
    ...<3 lines>...
        query_attrs=self.query_attrs,
        ^^^^^^^^^^^^^^^^^^^^^^^^^^^^^
    )
    ^
_mysql_connector.MySQLInterfaceError: Duplicate column name 'isim'

The above exception was the direct cause of the following exception:

Traceback (most recent call last):
  File "/Users/tuakpina/Projects/PythonProjects/PyQt6/CsvToSql/main.py", line 64, in run_button
    create_table(self.tablenametext,self.result.df)
    ~~~~~~~~~~~~^^^^^^^^^^^^^^^^^^^^^^^^^^^^^^^^^^^
  File "/Users/tuakpina/Projects/PythonProjects/PyQt6/CsvToSql/behaviour.py", line 35, in __init__
    self.add_column()
    ~~~~~~~~~~~~~~~^^
  File "/Users/tuakpina/Projects/PythonProjects/PyQt6/CsvToSql/behaviour.py", line 47, in add_column
    self.cursor.execute(f"ALTER TABLE {self.table_name} ADD COLUMN {i} {self.varchar}")
    ~~~~~~~~~~~~~~~~~~~^^^^^^^^^^^^^^^^^^^^^^^^^^^^^^^^^^^^^^^^^^^^^^^^^^^^^^^^^^^^^^^^
  File "/Library/Frameworks/Python.framework/Versions/3.13/lib/python3.13/site-packages/mysql/connector/cursor_cext.py", line 353, in execute
    self._connection.cmd_query(
    ~~~~~~~~~~~~~~~~~~~~~~~~~~^
        self._stmt_partition["mappable_stmt"],
        ^^^^^^^^^^^^^^^^^^^^^^^^^^^^^^^^^^^^^^
    ...<2 lines>...
        raw_as_string=self._raw_as_string,
        ^^^^^^^^^^^^^^^^^^^^^^^^^^^^^^^^^^
    )
    ^
  File "/Library/Frameworks/Python.framework/Versions/3.13/lib/python3.13/site-packages/mysql/connector/opentelemetry/context_propagation.py", line 97, in wrapper
    return method(cnx, *args, **kwargs)
  File "/Library/Frameworks/Python.framework/Versions/3.13/lib/python3.13/site-packages/mysql/connector/connection_cext.py", line 781, in cmd_query
    raise get_mysql_exception(
        err.errno, msg=err.msg, sqlstate=err.sqlstate
    ) from err
mysql.connector.errors.ProgrammingError: 1060 (42S21): Duplicate column name 'isim'
2025-10-14 12:48:14,638 - DEBUG - Programdan çıkış yapıldı

2025-10-14 12:49:54,708 - DEBUG - Program başlatıldı
2025-10-14 12:49:57,083 - DEBUG - Çalıştır butonuna basıldı
2025-10-14 12:49:57,084 - DEBUG - Kullanıcı değerleri girmeden çalıştır butonuna bastı
2025-10-14 12:50:02,604 - DEBUG - Programdan çıkış yapıldı

2025-10-14 13:03:55,014 - DEBUG - Program başlatıldı
2025-10-14 13:04:49,038 - DEBUG - Programdan çıkış yapıldı

2025-10-14 13:04:50,493 - DEBUG - Program başlatıldı
2025-10-14 13:05:02,041 - DEBUG - Programdan çıkış yapıldı

2025-10-14 13:05:03,872 - DEBUG - Program başlatıldı
2025-10-14 13:05:32,552 - DEBUG - Bir dosya seçildi --> /Users/tuakpina/Projects/PythonProjects/PyQt6/CsvToSql/rastgele_veri.csv
2025-10-14 13:05:46,623 - DEBUG - Çalıştır butonuna basıldı
2025-10-14 13:05:48,280 - DEBUG - add_column
2025-10-14 13:05:48,407 - ERROR - add_column_function: 1060 (42S21): Duplicate column name 'isim'
Traceback (most recent call last):
  File "/Library/Frameworks/Python.framework/Versions/3.13/lib/python3.13/site-packages/mysql/connector/connection_cext.py", line 772, in cmd_query
    self._cmysql.query(
    ~~~~~~~~~~~~~~~~~~^
        query,
        ^^^^^^
    ...<3 lines>...
        query_attrs=self.query_attrs,
        ^^^^^^^^^^^^^^^^^^^^^^^^^^^^^
    )
    ^
_mysql_connector.MySQLInterfaceError: Duplicate column name 'isim'

The above exception was the direct cause of the following exception:

Traceback (most recent call last):
  File "/Users/tuakpina/Projects/PythonProjects/PyQt6/CsvToSql/behaviour.py", line 50, in add_column
    self.cursor.execute(f"ALTER TABLE {self.table_name} ADD COLUMN {i} {self.varchar}")
    ~~~~~~~~~~~~~~~~~~~^^^^^^^^^^^^^^^^^^^^^^^^^^^^^^^^^^^^^^^^^^^^^^^^^^^^^^^^^^^^^^^^
  File "/Library/Frameworks/Python.framework/Versions/3.13/lib/python3.13/site-packages/mysql/connector/cursor_cext.py", line 353, in execute
    self._connection.cmd_query(
    ~~~~~~~~~~~~~~~~~~~~~~~~~~^
        self._stmt_partition["mappable_stmt"],
        ^^^^^^^^^^^^^^^^^^^^^^^^^^^^^^^^^^^^^^
    ...<2 lines>...
        raw_as_string=self._raw_as_string,
        ^^^^^^^^^^^^^^^^^^^^^^^^^^^^^^^^^^
    )
    ^
  File "/Library/Frameworks/Python.framework/Versions/3.13/lib/python3.13/site-packages/mysql/connector/opentelemetry/context_propagation.py", line 97, in wrapper
    return method(cnx, *args, **kwargs)
  File "/Library/Frameworks/Python.framework/Versions/3.13/lib/python3.13/site-packages/mysql/connector/connection_cext.py", line 781, in cmd_query
    raise get_mysql_exception(
        err.errno, msg=err.msg, sqlstate=err.sqlstate
    ) from err
mysql.connector.errors.ProgrammingError: 1060 (42S21): Duplicate column name 'isim'
2025-10-14 13:05:48,414 - DEBUG - insert_user
2025-10-14 13:06:53,472 - DEBUG - Çalıştır butonuna basıldı
2025-10-14 13:06:54,752 - DEBUG - add_column
2025-10-14 13:06:55,898 - DEBUG - insert_user
2025-10-14 13:07:12,489 - DEBUG - Programdan çıkış yapıldı

2025-10-14 14:44:35,977 - DEBUG - Program başlatıldı
2025-10-14 14:44:39,678 - DEBUG - Programdan çıkış yapıldı

2025-10-14 14:44:44,894 - DEBUG - Program başlatıldı
2025-10-14 14:44:57,327 - DEBUG - Programdan çıkış yapıldı

2025-10-14 14:47:14,579 - DEBUG - Program başlatıldı
2025-10-14 14:49:34,478 - DEBUG - Bir dosya seçildi --> /Users/tuakpina/Projects/PythonProjects/PyQt6/CsvToSql/rastgele_veri.csv
2025-10-14 14:49:50,368 - DEBUG - Çalıştır butonuna basıldı
2025-10-14 14:49:51,087 - DEBUG - add_column
2025-10-14 14:49:51,978 - DEBUG - insert_user
2025-10-14 14:51:24,076 - DEBUG - Programdan çıkış yapıldı

2025-10-14 14:52:32,086 - DEBUG - Program başlatıldı
2025-10-14 14:52:37,483 - DEBUG - Programdan çıkış yapıldı

2025-10-14 15:03:26,541 - DEBUG - Program başlatıldı
2025-10-14 15:04:31,858 - DEBUG - Program başlatıldı
2025-10-14 15:04:38,302 - DEBUG - Programdan çıkış yapıldı

2025-10-14 15:05:28,927 - DEBUG - Program başlatıldı
2025-10-14 15:05:34,816 - DEBUG - Programdan çıkış yapıldı

2025-10-14 15:06:17,673 - DEBUG - Program başlatıldı
2025-10-14 15:06:34,727 - DEBUG - Program başlatıldı
2025-10-14 15:08:19,233 - DEBUG - Programdan çıkış yapıldı

2025-10-14 15:13:38,825 - DEBUG - Program başlatıldı
2025-10-14 15:14:20,341 - DEBUG - Programdan çıkış yapıldı

2025-10-14 15:14:22,204 - DEBUG - Program başlatıldı
2025-10-14 15:15:55,802 - DEBUG - Programdan çıkış yapıldı

2025-10-14 15:15:57,899 - DEBUG - Program başlatıldı
2025-10-14 15:17:04,229 - DEBUG - Programdan çıkış yapıldı

2025-10-14 15:17:06,130 - DEBUG - Program başlatıldı
2025-10-14 15:17:34,898 - DEBUG - Programdan çıkış yapıldı

2025-10-14 15:17:36,744 - DEBUG - Program başlatıldı
2025-10-14 15:18:02,716 - DEBUG - Programdan çıkış yapıldı

2025-10-14 15:18:15,036 - DEBUG - Program başlatıldı
2025-10-14 15:18:24,213 - DEBUG - Programdan çıkış yapıldı

2025-10-16 20:50:29,157 - DEBUG - Program başlatıldı
2025-10-16 20:50:31,839 - DEBUG - Programdan çıkış yapıldı

2025-10-16 20:57:34,220 - DEBUG - Program başlatıldı
2025-10-16 20:57:44,566 - DEBUG - Bir dosya seçildi --> /Users/tuakpina/Projects/PythonProjects/PyQt6/CsvToSql/table_1.csv
2025-10-16 21:00:58,844 - DEBUG - Programdan çıkış yapıldı

2025-10-16 21:11:32,070 - DEBUG - Program başlatıldı
2025-10-16 21:11:36,926 - DEBUG - Programdan çıkış yapıldı

2025-10-16 21:15:06,945 - DEBUG - Program başlatıldı
2025-10-16 21:16:51,302 - DEBUG - Program başlatıldı
2025-10-16 21:18:09,110 - DEBUG - Program başlatıldı
2025-10-16 21:22:36,715 - DEBUG - Program başlatıldı
2025-10-16 21:22:57,296 - DEBUG - Program başlatıldı
2025-10-16 21:23:29,368 - DEBUG - Program başlatıldı
2025-10-16 21:25:13,653 - DEBUG - Programdan çıkış yapıldı

2025-10-16 21:25:15,141 - DEBUG - Program başlatıldı
2025-10-16 21:25:51,045 - DEBUG - Program başlatıldı
2025-10-16 21:26:04,554 - DEBUG - Programdan çıkış yapıldı

2025-10-16 21:27:50,421 - DEBUG - Program başlatıldı
2025-10-16 21:30:09,592 - DEBUG - Program başlatıldı
2025-10-16 21:30:41,939 - DEBUG - Program başlatıldı
2025-10-16 21:32:14,875 - DEBUG - Program başlatıldı
2025-10-16 21:33:05,710 - DEBUG - Program başlatıldı
2025-10-16 21:34:55,688 - DEBUG - Program başlatıldı
2025-10-17 00:13:08,718 - DEBUG - Program başlatıldı
2025-10-17 00:15:21,057 - DEBUG - Bir dosya seçildi --> /Users/tuakpina/Projects/PythonProjects/PyQt6/CsvToSql/rastgele_veri.csv
2025-10-17 00:15:34,249 - DEBUG - Çalıştır butonuna basıldı
2025-10-17 00:15:35,411 - DEBUG - add_column
2025-10-17 00:15:35,921 - DEBUG - insert_user
2025-10-17 00:16:32,652 - DEBUG - Programdan çıkış yapıldı

2025-10-17 16:28:50,550 - DEBUG - Program başlatıldı
2025-10-17 16:35:40,716 - DEBUG - Bir dosya seçildi --> /Users/tuakpina/Projects/PythonProjects/PyQt6/CsvToSql/rastgele_veri.csv
2025-10-17 16:35:58,960 - DEBUG - Çalıştır butonuna basıldı
2025-10-17 16:35:58,961 - DEBUG - Kullanıcı değerleri girmeden çalıştır butonuna bastı
2025-10-17 16:36:11,426 - DEBUG - Çalıştır butonuna basıldı
2025-10-17 16:36:12,514 - DEBUG - add_column
2025-10-17 16:36:13,485 - DEBUG - insert_user
2025-10-17 16:37:18,261 - DEBUG - Programdan çıkış yapıldı

2025-10-18 17:20:27,623 - DEBUG - Program başlatıldı
2025-10-18 17:21:56,878 - DEBUG - Bir dosya seçildi --> /Users/tuakpina/Projects/PythonProjects/PyQt6/CsvToSql/rastgele_veri.csv
2025-10-18 17:22:24,322 - DEBUG - Çalıştır butonuna basıldı
2025-10-18 17:22:28,181 - DEBUG - add_column
2025-10-18 17:22:30,083 - DEBUG - insert_user
2025-10-18 17:23:30,205 - DEBUG - Programdan çıkış yapıldı

2025-10-18 17:26:45,039 - DEBUG - Program başlatıldı
2025-10-18 17:26:48,418 - DEBUG - Çalıştır butonuna basıldı
2025-10-18 17:26:48,418 - DEBUG - Kullanıcı değerleri girmeden çalıştır butonuna bastı
2025-10-18 17:26:55,571 - DEBUG - Programdan çıkış yapıldı

2025-10-18 17:26:59,086 - DEBUG - Program başlatıldı
2025-10-18 17:27:03,184 - DEBUG - Bir dosya seçildi --> 
2025-10-18 17:27:04,953 - DEBUG - Programdan çıkış yapıldı

2025-10-20 16:08:48,280 - DEBUG - Program başlatıldı
2025-10-20 16:10:22,144 - DEBUG - Bir dosya seçildi --> 
2025-10-20 16:10:31,010 - DEBUG - Programdan çıkış yapıldı

2025-10-20 16:12:23,965 - DEBUG - Program başlatıldı
2025-10-20 16:13:07,871 - DEBUG - Bir dosya seçildi --> /Users/tuakpina/Projects/PythonProjects/PyQt6/CsvToSql/rastgele_veri.csv
2025-10-20 16:26:55,018 - DEBUG - Çalıştır butonuna basıldı
2025-10-20 16:26:56,840 - DEBUG - add_column
2025-10-20 16:26:58,043 - DEBUG - insert_user
2025-10-20 16:27:17,901 - DEBUG - Çalıştır butonuna basıldı
2025-10-20 16:27:19,018 - DEBUG - add_column
2025-10-20 16:27:20,105 - DEBUG - insert_user
2025-10-20 16:39:50,444 - DEBUG - Programdan çıkış yapıldı

